<?xml version="1.0" encoding="utf-8"?>
<robot name="glr_trailer_gazebo" xmlns:xacro="http://ros.org/wiki/xacro">

  <!-- ============================================ -->
  <!-- TRAILER GAZEBO MATERIAL DEFINITIONS -->
  <!-- ============================================ -->

  <gazebo reference="cambao">
    <material>Gazebo/Grey</material>
  </gazebo>

  <gazebo reference="trailer_footprint">
    <material>Gazebo/Orange</material>
  </gazebo>

  <gazebo reference="rodeirodiant1">
    <material>Gazebo/Orange</material>
  </gazebo>

  <gazebo reference="rodeirodiant2">
    <material>Gazebo/Orange</material>
  </gazebo>

  <gazebo reference="rodadiant1">
    <material>Gazebo/Black</material>
  </gazebo>

  <gazebo reference="rodadiant2">
    <material>Gazebo/Black</material>
  </gazebo>

  <gazebo reference="rodeirotras1">
    <material>Gazebo/Orange</material>
  </gazebo>

  <gazebo reference="rodeirotras2">
    <material>Gazebo/Orange</material>
  </gazebo>

  <gazebo reference="rodatras1">
    <material>Gazebo/Black</material>
  </gazebo>

  <gazebo reference="rodatras2">
    <material>Gazebo/Black</material>
  </gazebo>

  <!-- ============================================ -->
  <!-- TRAILER WHEEL JOINT DEFINITIONS -->
  <!-- ============================================ -->
  
  <gazebo>
    <joint name='barradiant1_JOINT_1' type='revolute'>
      <parent>barradiant1</parent>
      <child>rodeirodiant1</child>
      <pose>-0.06 0.185 -0.027 0 -0 0</pose>
      <axis>
        <xyz>0 0 1</xyz>
        <limit>
          <lower>-1.79769e+308</lower>
          <upper>1.79769e+308</upper>
          <effort>0</effort>
          <velocity>0</velocity>
        </limit>
        <dynamics>
          <spring_reference>0</spring_reference>
          <spring_stiffness>0</spring_stiffness>
          <damping>0</damping>
          <friction>1.2</friction>
        </dynamics>
      </axis>
      <physics>
        <ode>
          <limit>
            <cfm>0</cfm>
            <erp>0.2</erp>
          </limit>
          <suspension>
            <cfm>0</cfm>
            <erp>0.2</erp>
          </suspension>
        </ode>
      </physics>
    </joint>

    <joint name='barradiant2_JOINT_2' type='revolute'>
      <parent>barradiant2</parent>
      <child>rodeirodiant2</child>
      <pose>0.06 0.185 -0.027 0 -0 0</pose>
      <axis>
        <xyz>0 0 1</xyz>
        <limit>
          <lower>-1.79769e+308</lower>
          <upper>1.79769e+308</upper>
          <effort>0</effort>
          <velocity>0</velocity>
        </limit>
        <dynamics>
          <spring_reference>0</spring_reference>
          <spring_stiffness>0</spring_stiffness>
          <damping>0</damping>
          <friction>1.2</friction>
        </dynamics>
      </axis>
      <physics>
        <ode>
          <limit>
            <cfm>0</cfm>
            <erp>0.2</erp>
          </limit>
          <suspension>
            <cfm>0</cfm>
            <erp>0.2</erp>
          </suspension>
        </ode>
      </physics>
    </joint>

    <joint name='barratras1_JOINT_3' type='revolute'>
      <parent>barratras1</parent>
      <child>rodeirotras1</child>
      <pose>-0.18 0 -0.08 0 -0 0</pose>
      <axis>
        <xyz>0 0 1</xyz>
        <limit>
          <lower>-1.79769e+308</lower>
          <upper>1.79769e+308</upper>
          <effort>0</effort>
          <velocity>0</velocity>
        </limit>
        <dynamics>
          <spring_reference>0</spring_reference>
          <spring_stiffness>0</spring_stiffness>
          <damping>0</damping>
          <friction>1.2</friction>
        </dynamics>
      </axis>
      <physics>
        <ode>
          <limit>
            <cfm>0</cfm>
            <erp>0.2</erp>
          </limit>
          <suspension>
            <cfm>0</cfm>
            <erp>0.2</erp>
          </suspension>
        </ode>
      </physics>
    </joint>

    <joint name='barratras2_JOINT_4' type='revolute'>
      <parent>barratras2</parent>
      <child>rodeirotras2</child>
      <pose>0.18 0 -0.08 0 -0 0</pose>
      <axis>
        <xyz>0 0 1</xyz>
        <limit>
          <lower>-1.79769e+308</lower>
          <upper>1.79769e+308</upper>
          <effort>0</effort>
          <velocity>0</velocity>
        </limit>
        <dynamics>
          <spring_reference>0</spring_reference>
          <spring_stiffness>0</spring_stiffness>
          <damping>0</damping>
          <friction>1.2</friction>
        </dynamics>
      </axis>
      <physics>
        <ode>
          <limit>
            <cfm>0</cfm>
            <erp>0.2</erp>
          </limit>
          <suspension>
            <cfm>0</cfm>
            <erp>0.2</erp>
          </suspension>
        </ode>
      </physics>
    </joint>
  </gazebo>

</robot>
