<?xml version="1.0" encoding="utf-8"?>
<robot name="glr_gazebo" xmlns:xacro="http://ros.org/wiki/xacro">

  <!-- ============================================ -->
  <!-- GAZEBO MATERIAL DEFINITIONS -->
  <!-- ============================================ -->
  
  <gazebo reference="chassibigga">
    <material>Gazebo/Orange</material>
  </gazebo>

  <gazebo reference="left_wheel">
    <material>Gazebo/Black</material>
    <mu1>1.0</mu1>
    <mu2>1.0</mu2>
  </gazebo>

  <gazebo reference="right_wheel">
    <material>Gazebo/Black</material>
    <mu1>1.0</mu1>
    <mu2>1.0</mu2>
  </gazebo>

  <gazebo reference="hitch_link">
    <material>Gazebo/DarkGrey</material>
  </gazebo>

  <gazebo reference="cambao">
    <material>Gazebo/Grey</material>
  </gazebo>

  <gazebo reference="chassi">
    <material>Gazebo/Orange</material>
  </gazebo>

  <gazebo reference="rodeirodiant1">
    <material>Gazebo/Orange</material>
  </gazebo>

  <gazebo reference="rodeirodiant2">
    <material>Gazebo/Orange</material>
  </gazebo>

  <gazebo reference="rodadiant1">
    <material>Gazebo/Black</material>
  </gazebo>

  <gazebo reference="rodadiant2">
    <material>Gazebo/Black</material>
  </gazebo>

  <gazebo reference="rodeirotras1">
    <material>Gazebo/Orange</material>
  </gazebo>

  <gazebo reference="rodeirotras2">
    <material>Gazebo/Orange</material>
  </gazebo>

  <gazebo reference="rodatras1">
    <material>Gazebo/Black</material>
  </gazebo>

  <gazebo reference="rodatras2">
    <material>Gazebo/Black</material>
  </gazebo>

  <!-- ============================================ -->
  <!-- DIFFERENTIAL DRIVE PLUGIN -->
  <!-- ============================================ -->
  
  <gazebo>
    <plugin name="differential_drive_controller" filename="libgazebo_ros_diff_drive.so">
      <ros>
        <remapping>cmd_vel:=cmd_vel</remapping>
        <remapping>odom:=odom</remapping>
      </ros>

      <update_rate>100.0</update_rate>

      <left_joint>left_wheel_joint</left_joint>
      <right_joint>right_wheel_joint</right_joint>

      <wheel_separation>0.5</wheel_separation>
      <wheel_diameter>0.2</wheel_diameter>

      <max_wheel_torque>200</max_wheel_torque>
      <max_wheel_acceleration>10.0</max_wheel_acceleration>

      <publish_odom>true</publish_odom>
      <publish_odom_tf>true</publish_odom_tf>
      <publish_wheel_tf>true</publish_wheel_tf>

      <odometry_frame>odom</odometry_frame>
      <robot_base_frame>base_link</robot_base_frame>
    </plugin>
  </gazebo>

  <!-- ============================================ -->
  <!-- LIDAR SENSOR PLUGIN -->
  <!-- ============================================ -->
  
  <gazebo reference="lidar_link">
    <material>Gazebo/DarkGrey</material>
    <sensor type="ray" name="lidar_sensor">
      <pose>0 0 0 0 0 0</pose>
      <visualize>false</visualize>
      <update_rate>10</update_rate>
      <ray>
        <scan>
          <horizontal>
            <samples>360</samples>
            <resolution>1</resolution>
            <min_angle>-3.14159</min_angle>
            <max_angle>3.14159</max_angle>
          </horizontal>
        </scan>
        <range>
          <min>0.1</min>
          <max>30.0</max>
          <resolution>0.01</resolution>
        </range>
        <noise>
          <type>gaussian</type>
          <mean>0.0</mean>
          <stddev>0.01</stddev>
        </noise>
      </ray>
      <plugin name="gazebo_ros_lidar" filename="libgazebo_ros_ray_sensor.so">
        <ros>
          <namespace>/glr_description</namespace>
          <remapping>~/out:=scan</remapping>
        </ros>
        <output_type>sensor_msgs/LaserScan</output_type>
        <frame_name>lidar_link</frame_name>
      </plugin>
    </sensor>
  </gazebo>

  <!-- ============================================ -->
  <!-- TRAILER WHEEL JOINT DEFINITIONS -->
  <!-- ============================================ -->
  
  <gazebo>
    <joint name='barradiant1_JOINT_1' type='revolute'>
      <parent>barradiant1</parent>
      <child>rodeirodiant1</child>
      <pose>-0.06 0.185 -0.027 0 -0 0</pose>
      <axis>
        <xyz>0 0 1</xyz>
        <limit>
          <lower>-1.79769e+308</lower>
          <upper>1.79769e+308</upper>
          <effort>0</effort>
          <velocity>0</velocity>
        </limit>
        <dynamics>
          <spring_reference>0</spring_reference>
          <spring_stiffness>0</spring_stiffness>
          <damping>0</damping>
          <friction>1.2</friction>
        </dynamics>
      </axis>
      <physics>
        <ode>
          <limit>
            <cfm>0</cfm>
            <erp>0.2</erp>
          </limit>
          <suspension>
            <cfm>0</cfm>
            <erp>0.2</erp>
          </suspension>
        </ode>
      </physics>
    </joint>

    <joint name='barradiant2_JOINT_2' type='revolute'>
      <parent>barradiant2</parent>
      <child>rodeirodiant2</child>
      <pose>0.06 0.185 -0.027 0 -0 0</pose>
      <axis>
        <xyz>0 0 1</xyz>
        <limit>
          <lower>-1.79769e+308</lower>
          <upper>1.79769e+308</upper>
          <effort>0</effort>
          <velocity>0</velocity>
        </limit>
        <dynamics>
          <spring_reference>0</spring_reference>
          <spring_stiffness>0</spring_stiffness>
          <damping>0</damping>
          <friction>1.2</friction>
        </dynamics>
      </axis>
      <physics>
        <ode>
          <limit>
            <cfm>0</cfm>
            <erp>0.2</erp>
          </limit>
          <suspension>
            <cfm>0</cfm>
            <erp>0.2</erp>
          </suspension>
        </ode>
      </physics>
    </joint>

    <joint name='barratras1_JOINT_3' type='revolute'>
      <parent>barratras1</parent>
      <child>rodeirotras1</child>
      <pose>-0.18 0 -0.08 0 -0 0</pose>
      <axis>
        <xyz>0 0 1</xyz>
        <limit>
          <lower>-1.79769e+308</lower>
          <upper>1.79769e+308</upper>
          <effort>0</effort>
          <velocity>0</velocity>
        </limit>
        <dynamics>
          <spring_reference>0</spring_reference>
          <spring_stiffness>0</spring_stiffness>
          <damping>0</damping>
          <friction>1.2</friction>
        </dynamics>
      </axis>
      <physics>
        <ode>
          <limit>
            <cfm>0</cfm>
            <erp>0.2</erp>
          </limit>
          <suspension>
            <cfm>0</cfm>
            <erp>0.2</erp>
          </suspension>
        </ode>
      </physics>
    </joint>

    <joint name='barratras2_JOINT_4' type='revolute'>
      <parent>barratras2</parent>
      <child>rodeirotras2</child>
      <pose>0.18 0 -0.08 0 -0 0</pose>
      <axis>
        <xyz>0 0 1</xyz>
        <limit>
          <lower>-1.79769e+308</lower>
          <upper>1.79769e+308</upper>
          <effort>0</effort>
          <velocity>0</velocity>
        </limit>
        <dynamics>
          <spring_reference>0</spring_reference>
          <spring_stiffness>0</spring_stiffness>
          <damping>0</damping>
          <friction>1.2</friction>
        </dynamics>
      </axis>
      <physics>
        <ode>
          <limit>
            <cfm>0</cfm>
            <erp>0.2</erp>
          </limit>
          <suspension>
            <cfm>0</cfm>
            <erp>0.2</erp>
          </suspension>
        </ode>
      </physics>
    </joint>
  </gazebo>

</robot>
